<?xml version="1.0" ?>
<robot name="simple_model">
  <joint name="simple_model__link_1_JOINT_0" type="revolute">
    <parent link="simple_model__link_1"/>
    <child link="simple_model__link_0"/>
    <origin rpy="-1.5708  0      0" xyz="0.08164 -0.20119  0.5"/>
    <axis xyz="0 -1  0"/>
    <limit effort="-1.0" lower="-1.79769e+308" upper="1.79769e+308" velocity="-1.0"/>
  </joint>
  <link name="simple_model__link_0">
    <inertial>
      <mass value="0.129655"/>
      <origin rpy="0  0  0" xyz="0  0  0"/>
      <inertia ixx="0.00828505" ixy="0" ixz="0" iyy="0.00828505" iyz="0" izz="0.0162068"/>
    </inertial>
    <collision name="simple_model__collision">
      <origin rpy="0  0  0" xyz="0  0  0"/>
      <geometry>
        <cylinder length="0.129655" radius="0.5"/>
      </geometry>
    </collision>
    <visual name="simple_model__visual">
      <origin rpy="0  0  0" xyz="0  0  0"/>
      <geometry>
        <cylinder length="0.129655" radius="0.5"/>
      </geometry>
    </visual>
  </link>
  <link name="simple_model__link_1">
    <inertial>
      <mass value="1"/>
      <origin rpy="0  0  0" xyz="0  0  0"/>
      <inertia ixx="0.166667" ixy="0" ixz="0" iyy="0.166667" iyz="0" izz="0.166667"/>
    </inertial>
    <collision name="simple_model__collision">
      <origin rpy="0  0  0" xyz="0.08703  0.37137  0.5"/>
      <geometry>
        <box size="1 1 1"/>
      </geometry>
    </collision>
    <visual name="simple_model__visual">
      <origin rpy="0  0  0" xyz="0.08703  0.37137  0.5"/>
      <geometry>
        <box size="1 1 1"/>
      </geometry>
    </visual>
  </link>
</robot>
